Workbook
Name SizesForSearch: 'Списки поиска'!$A$1:$A$85

Sheet Поиск параметров
A1: ПОИСК ПАРАМЕТРОВ
B4: 1. Источник данных | D4: 1ST
B5: 2. Размер Size | D5: 175/65R14
B6: 3. Текст заголовка первой строки (например: Size, Code, Mass)
B8: Найдено параметров | D8: =SUM('Каталог поиска'!E2:E998) -> 535
A9: Выберите 1ST или 2ST, затем Size. Введите часть названия в D6; пустое поле показывает все заголовки первой строки. Среднее и количество заполняются только для расчётных числовых параметров. Регистр букв не важен.
A12: № | B12: Параметр | C12: Столбец | D12: Среднее | E12: Числовых значений
A13: =IF(F13="","",1) -> 1 | B13: =IF($F13="","",INDEX('Каталог поиска'!$B$2:$B$998,$F13)) -> Building Size | C13: =IF($F13="","",INDEX('Каталог поиска'!$C$2:$C$998,$F13)) -> A | D13: =IF(OR($F13="",E13=0,INDEX('Каталог поиска'!$D$2:$D$998,$F13)=0),"",IFERROR(INDEX('По размерам'!$A$2:$TY$86,MATCH($D$5,'По размерам'!$A$2:$A$86,0),INDEX('Каталог поиска'!$D$2:$D$998,$F13)),"")) | E13: =IF(OR($F13="",INDEX('Каталог поиска'!$D$2:$D$998,$F13)=0),"",IFERROR(INDEX('Количество значений'!$A$2:$TY$86,MATCH($D$5,'Количество значений'!$A$2:$A$86,0),INDEX('Каталог поиска'!$D$2:$D$998,$F13)),"")) | F13: =IFERROR(MATCH(1,'Каталог поиска'!$F$2:$F$998,0),"") -> 1
A14: =IF(F14="","",2) -> 2 | B14: =IF($F14="","",INDEX('Каталог поиска'!$B$2:$B$998,$F14)) -> Revision No | C14: =IF($F14="","",INDEX('Каталог поиска'!$C$2:$C$998,$F14)) -> B | D14: =IF(OR($F14="",E14=0,INDEX('Каталог поиска'!$D$2:$D$998,$F14)=0),"",IFERROR(INDEX('По размерам'!$A$2:$TY$86,MATCH($D$5,'По размерам'!$A$2:$A$86,0),INDEX('Каталог поиска'!$D$2:$D$998,$F14)),"")) | E14: =IF(OR($F14="",INDEX('Каталог поиска'!$D$2:$D$998,$F14)=0),"",IFERROR(INDEX('Количество значений'!$A$2:$TY$86,MATCH($D$5,'Количество значений'!$A$2:$A$86,0),INDEX('Каталог поиска'!$D$2:$D$998,$F14)),"")) | F14: =IFERROR(MATCH(2,'Каталог поиска'!$F$2:$F$998,0),"") -> 2
A15: =IF(F15="","",3) -> 3 | B15: =IF($F15="","",INDEX('Каталог поиска'!$B$2:$B$998,$F15)) -> APPROVE STATE | C15: =IF($F15="","",INDEX('Каталог поиска'!$C$2:$C$998,$F15)) -> C | D15: =IF(OR($F15="",E15=0,INDEX('Каталог поиска'!$D$2:$D$998,$F15)=0),"",IFERROR(INDEX('По размерам'!$A$2:$TY$86,MATCH($D$5,'По размерам'!$A$2:$A$86,0),INDEX('Каталог поиска'!$D$2:$D$998,$F15)),"")) | E15: =IF(OR($F15="",INDEX('Каталог поиска'!$D$2:$D$998,$F15)=0),"",IFERROR(INDEX('Количество значений'!$A$2:$TY$86,MATCH($D$5,'Количество значений'!$A$2:$A$86,0),INDEX('Каталог поиска'!$D$2:$D$998,$F15)),"")) | F15: =IFERROR(MATCH(3,'Каталог поиска'!$F$2:$F$998,0),"") -> 3
A16: =IF(F16="","",4) -> 4 | B16: =IF($F16="","",INDEX('Каталог поиска'!$B$2:$B$998,$F16)) -> Issue date | C16: =IF($F16="","",INDEX('Каталог поиска'!$C$2:$C$998,$F16)) -> D | D16: =IF(OR($F16="",E16=0,INDEX('Каталог поиска'!$D$2:$D$998,$F16)=0),"",IFERROR(INDEX('По размерам'!$A$2:$TY$86,MATCH($D$5,'По размерам'!$A$2:$A$86,0),INDEX('Каталог поиска'!$D$2:$D$998,$F16)),"")) | E16: =IF(OR($F16="",INDEX('Каталог поиска'!$D$2:$D$998,$F16)=0),"",IFERROR(INDEX('Количество значений'!$A$2:$TY$86,MATCH($D$5,'Количество значений'!$A$2:$A$86,0),INDEX('Каталог поиска'!$D$2:$D$998,$F16)),"")) | F16: =IFERROR(MATCH(4,'Каталог поиска'!$F$2:$F$998,0),"") -> 4
A17: =IF(F17="","",5) -> 5 | B17: =IF($F17="","",INDEX('Каталог поиска'!$B$2:$B$998,$F17)) -> Application date | C17: =IF($F17="","",INDEX('Каталог поиска'!$C$2:$C$998,$F17)) -> E | D17: =IF(OR($F17="",E17=0,INDEX('Каталог поиска'!$D$2:$D$998,$F17)=0),"",IFERROR(INDEX('По размерам'!$A$2:$TY$86,MATCH($D$5,'По размерам'!$A$2:$A$86,0),INDEX('Каталог поиска'!$D$2:$D$998,$F17)),"")) | E17: =IF(OR($F17="",INDEX('Каталог поиска'!$D$2:$D$998,$F17)=0),"",IFERROR(INDEX('Количество значений'!$A$2:$TY$86,MATCH($D$5,'Количество значений'!$A$2:$A$86,0),INDEX('Каталог поиска'!$D$2:$D$998,$F17)),"")) | F17: =IFERROR(MATCH(5,'Каталог поиска'!$F$2:$F$998,0),"") -> 5
A18: =IF(F18="","",6) -> 6 | B18: =IF($F18="","",INDEX('Каталог поиска'!$B$2:$B$998,$F18)) -> Issue reason | C18: =IF($F18="","",INDEX('Каталог поиска'!$C$2:$C$998,$F18)) -> F | D18: =IF(OR($F18="",E18=0,INDEX('Каталог поиска'!$D$2:$D$998,$F18)=0),"",IFERROR(INDEX('По размерам'!$A$2:$TY$86,MATCH($D$5,'По размерам'!$A$2:$A$86,0),INDEX('Каталог поиска'!$D$2:$D$998,$F18)),"")) | E18: =IF(OR($F18="",INDEX('Каталог поиска'!$D$2:$D$998,$F18)=0),"",IFERROR(INDEX('Количество значений'!$A$2:$TY$86,MATCH($D$5,'Количество значений'!$A$2:$A$86,0),INDEX('Каталог поиска'!$D$2:$D$998,$F18)),"")) | F18: =IFERROR(MATCH(6,'Каталог поиска'!$F$2:$F$998,0),"") -> 6
A19: =IF(F19="","",7) -> 7 | B19: =IF($F19="","",INDEX('Каталог поиска'!$B$2:$B$998,$F19)) -> Engineer | C19: =IF($F19="","",INDEX('Каталог поиска'!$C$2:$C$998,$F19)) -> G | D19: =IF(OR($F19="",E19=0,INDEX('Каталог поиска'!$D$2:$D$998,$F19)=0),"",IFERROR(INDEX('По размерам'!$A$2:$TY$86,MATCH($D$5,'По размерам'!$A$2:$A$86,0),INDEX('Каталог поиска'!$D$2:$D$998,$F19)),"")) | E19: =IF(OR($F19="",INDEX('Каталог поиска'!$D$2:$D$998,$F19)=0),"",IFERROR(INDEX('Количество значений'!$A$2:$TY$86,MATCH($D$5,'Количество значений'!$A$2:$A$86,0),INDEX('Каталог поиска'!$D$2:$D$998,$F19)),"")) | F19: =IFERROR(MATCH(7,'Каталог поиска'!$F$2:$F$998,0),"") -> 7
A20: =IF(F20="","",8) -> 8 | B20: =IF($F20="","",INDEX('Каталог поиска'!$B$2:$B$998,$F20)) -> Checked by | C20: =IF($F20="","",INDEX('Каталог поиска'!$C$2:$C$998,$F20)) -> H | D20: =IF(OR($F20="",E20=0,INDEX('Каталог поиска'!$D$2:$D$998,$F20)=0),"",IFERROR(INDEX('По размерам'!$A$2:$TY$86,MATCH($D$5,'По размерам'!$A$2:$A$86,0),INDEX('Каталог поиска'!$D$2:$D$998,$F20)),"")) | E20: =IF(OR($F20="",INDEX('Каталог поиска'!$D$2:$D$998,$F20)=0),"",IFERROR(INDEX('Количество значений'!$A$2:$TY$86,MATCH($D$5,'Количество значений'!$A$2:$A$86,0),INDEX('Каталог поиска'!$D$2:$D$998,$F20)),"")) | F20: =IFERROR(MATCH(8,'Каталог поиска'!$F$2:$F$998,0),"") -> 8
A21: =IF(F21="","",9) -> 9 | B21: =IF($F21="","",INDEX('Каталог поиска'!$B$2:$B$998,$F21)) -> Checked by DSC/SC | C21: =IF($F21="","",INDEX('Каталог поиска'!$C$2:$C$998,$F21)) -> I | D21: =IF(OR($F21="",E21=0,INDEX('Каталог поиска'!$D$2:$D$998,$F21)=0),"",IFERROR(INDEX('По размерам'!$A$2:$TY$86,MATCH($D$5,'По размерам'!$A$2:$A$86,0),INDEX('Каталог поиска'!$D$2:$D$998,$F21)),"")) | E21: =IF(OR($F21="",INDEX('Каталог поиска'!$D$2:$D$998,$F21)=0),"",IFERROR(INDEX('Количество значений'!$A$2:$TY$86,MATCH($D$5,'Количество значений'!$A$2:$A$86,0),INDEX('Каталог поиска'!$D$2:$D$998,$F21)),"")) | F21: =IFERROR(MATCH(9,'Каталог поиска'!$F$2:$F$998,0),"") -> 9
A22: =IF(F22="","",10) -> 10 | B22: =IF($F22="","",INDEX('Каталог поиска'!$B$2:$B$998,$F22)) -> Approved by | C22: =IF($F22="","",INDEX('Каталог поиска'!$C$2:$C$998,$F22)) -> J | D22: =IF(OR($F22="",E22=0,INDEX('Каталог поиска'!$D$2:$D$998,$F22)=0),"",IFERROR(INDEX('По размерам'!$A$2:$TY$86,MATCH($D$5,'По размерам'!$A$2:$A$86,0),INDEX('Каталог поиска'!$D$2:$D$998,$F22)),"")) | E22: =IF(OR($F22="",INDEX('Каталог поиска'!$D$2:$D$998,$F22)=0),"",IFERROR(INDEX('Количество значений'!$A$2:$TY$86,MATCH($D$5,'Количество значений'!$A$2:$A$86,0),INDEX('Каталог поиска'!$D$2:$D$998,$F22)),"")) | F22: =IFERROR(MATCH(10,'Каталог поиска'!$F$2:$F$998,0),"") -> 10
A23: =IF(F23="","",11) -> 11 | B23: =IF($F23="","",INDEX('Каталог поиска'!$B$2:$B$998,$F23)) -> Process code No. | C23: =IF($F23="","",INDEX('Каталог поиска'!$C$2:$C$998,$F23)) -> K | D23: =IF(OR($F23="",E23=0,INDEX('Каталог поиска'!$D$2:$D$998,$F23)=0),"",IFERROR(INDEX('По размерам'!$A$2:$TY$86,MATCH($D$5,'По размерам'!$A$2:$A$86,0),INDEX('Каталог поиска'!$D$2:$D$998,$F23)),"")) | E23: =IF(OR($F23="",INDEX('Каталог поиска'!$D$2:$D$998,$F23)=0),"",IFERROR(INDEX('Количество значений'!$A$2:$TY$86,MATCH($D$5,'Количество значений'!$A$2:$A$86,0),INDEX('Каталог поиска'!$D$2:$D$998,$F23)),"")) | F23: =IFERROR(MATCH(11,'Каталог поиска'!$F$2:$F$998,0),"") -> 11
A24: =IF(F24="","",12) -> 12 | B24: =IF($F24="","",INDEX('Каталог поиска'!$B$2:$B$998,$F24)) -> CPU No. | C24: =IF($F24="","",INDEX('Каталог поиска'!$C$2:$C$998,$F24)) -> L | D24: =IF(OR($F24="",E24=0,INDEX('Каталог поиска'!$D$2:$D$998,$F24)=0),"",IFERROR(INDEX('По размерам'!$A$2:$TY$86,MATCH($D$5,'По размерам'!$A$2:$A$86,0),INDEX('Каталог поиска'!$D$2:$D$998,$F24)),"")) | E24: =IF(OR($F24="",INDEX('Каталог поиска'!$D$2:$D$998,$F24)=0),"",IFERROR(INDEX('Количество значений'!$A$2:$TY$86,MATCH($D$5,'Количество значений'!$A$2:$A$86,0),INDEX('Каталог поиска'!$D$2:$D$998,$F24)),"")) | F24: =IFERROR(MATCH(12,'Каталог поиска'!$F$2:$F$998,0),"") -> 12
A25: =IF(F25="","",13) -> 13 | B25: =IF($F25="","",INDEX('Каталог поиска'!$B$2:$B$998,$F25)) -> Deletion No. | C25: =IF($F25="","",INDEX('Каталог поиска'!$C$2:$C$998,$F25)) -> M | D25: =IF(OR($F25="",E25=0,INDEX('Каталог поиска'!$D$2:$D$998,$F25)=0),"",IFERROR(INDEX('По размерам'!$A$2:$TY$86,MATCH($D$5,'По размерам'!$A$2:$A$86,0),INDEX('Каталог поиска'!$D$2:$D$998,$F25)),"")) | E25: =IF(OR($F25="",INDEX('Каталог поиска'!$D$2:$D$998,$F25)=0),"",IFERROR(INDEX('Количество значений'!$A$2:$TY$86,MATCH($D$5,'Количество значений'!$A$2:$A$86,0),INDEX('Каталог поиска'!$D$2:$D$998,$F25)),"")) | F25: =IFERROR(MATCH(13,'Каталог поиска'!$F$2:$F$998,0),"") -> 13
A26: =IF(F26="","",14) -> 14 | B26: =IF($F26="","",INDEX('Каталог поиска'!$B$2:$B$998,$F26)) -> Production M/C | C26: =IF($F26="","",INDEX('Каталог поиска'!$C$2:$C$998,$F26)) -> N | D26: =IF(OR($F26="",E26=0,INDEX('Каталог поиска'!$D$2:$D$998,$F26)=0),"",IFERROR(INDEX('По размерам'!$A$2:$TY$86,MATCH($D$5,'По размерам'!$A$2:$A$86,0),INDEX('Каталог поиска'!$D$2:$D$998,$F26)),"")) | E26: =IF(OR($F26="",INDEX('Каталог поиска'!$D$2:$D$998,$F26)=0),"",IFERROR(INDEX('Количество значений'!$A$2:$TY$86,MATCH($D$5,'Количество значений'!$A$2:$A$86,0),INDEX('Каталог поиска'!$D$2:$D$998,$F26)),"")) | F26: =IFERROR(MATCH(14,'Каталог поиска'!$F$2:$F$998,0),"") -> 14
A27: =IF(F27="","",15) -> 15 | B27: =IF($F27="","",INDEX('Каталог поиска'!$B$2:$B$998,$F27)) -> Production type | C27: =IF($F27="","",INDEX('Каталог поиска'!$C$2:$C$998,$F27)) -> O | D27: =IF(OR($F27="",E27=0,INDEX('Каталог поиска'!$D$2:$D$998,$F27)=0),"",IFERROR(INDEX('По размерам'!$A$2:$TY$86,MATCH($D$5,'По размерам'!$A$2:$A$86,0),INDEX('Каталог поиска'!$D$2:$D$998,$F27)),"")) | E27: =IF(OR($F27="",INDEX('Каталог поиска'!$D$2:$D$998,$F27)=0),"",IFERROR(INDEX('Количество значений'!$A$2:$TY$86,MATCH($D$5,'Количество значений'!$A$2:$A$86,0),INDEX('Каталог поиска'!$D$2:$D$998,$F27)),"")) | F27: =IFERROR(MATCH(15,'Каталог поиска'!$F$2:$F$998,0),"") -> 15
A28: =IF(F28="","",16) -> 16 | B28: =IF($F28="","",INDEX('Каталог поиска'!$B$2:$B$998,$F28)) -> Trial type | C28: =IF($F28="","",INDEX('Каталог поиска'!$C$2:$C$998,$F28)) -> P | D28: =IF(OR($F28="",E28=0,INDEX('Каталог поиска'!$D$2:$D$998,$F28)=0),"",IFERROR(INDEX('По размерам'!$A$2:$TY$86,MATCH($D$5,'По размерам'!$A$2:$A$86,0),INDEX('Каталог поиска'!$D$2:$D$998,$F28)),"")) | E28: =IF(OR($F28="",INDEX('Каталог поиска'!$D$2:$D$998,$F28)=0),"",IFERROR(INDEX('Количество значений'!$A$2:$TY$86,MATCH($D$5,'Количество значений'!$A$2:$A$86,0),INDEX('Каталог поиска'!$D$2:$D$998,$F28)),"")) | F28: =IFERROR(MATCH(16,'Каталог поиска'!$F$2:$F$998,0),"") -> 16
A29: =IF(F29="","",17) -> 17 | B29: =IF($F29="","",INDEX('Каталог поиска'!$B$2:$B$998,$F29)) -> 2nd production code | C29: =IF($F29="","",INDEX('Каталог поиска'!$C$2:$C$998,$F29)) -> Q | D29: =IF(OR($F29="",E29=0,INDEX('Каталог поиска'!$D$2:$D$998,$F29)=0),"",IFERROR(INDEX('По размерам'!$A$2:$TY$86,MATCH($D$5,'По размерам'!$A$2:$A$86,0),INDEX('Каталог поиска'!$D$2:$D$998,$F29)),"")) | E29: =IF(OR($F29="",INDEX('Каталог поиска'!$D$2:$D$998,$F29)=0),"",IFERROR(INDEX('Количество значений'!$A$2:$TY$86,MATCH($D$5,'Количество значений'!$A$2:$A$86,0),INDEX('Каталог поиска'!$D$2:$D$998,$F29)),"")) | F29: =IFERROR(MATCH(17,'Каталог поиска'!$F$2:$F$998,0),"") -> 17
A30: =IF(F30="","",18) -> 18 | B30: =IF($F30="","",INDEX('Каталог поиска'!$B$2:$B$998,$F30)) -> Group | C30: =IF($F30="","",INDEX('Каталог поиска'!$C$2:$C$998,$F30)) -> R | D30: =IF(OR($F30="",E30=0,INDEX('Каталог поиска'!$D$2:$D$998,$F30)=0),"",IFERROR(INDEX('По размерам'!$A$2:$TY$86,MATCH($D$5,'По размерам'!$A$2:$A$86,0),INDEX('Каталог поиска'!$D$2:$D$998,$F30)),"")) | E30: =IF(OR($F30="",INDEX('Каталог поиска'!$D$2:$D$998,$F30)=0),"",IFERROR(INDEX('Количество значений'!$A$2:$TY$86,MATCH($D$5,'Количество значений'!$A$2:$A$86,0),INDEX('Каталог поиска'!$D$2:$D$998,$F30)),"")) | F30: =IFERROR(MATCH(18,'Каталог поиска'!$F$2:$F$998,0),"") -> 18
A31: =IF(F31="","",19) -> 19 | B31: =IF($F31="","",INDEX('Каталог поиска'!$B$2:$B$998,$F31)) -> Size | C31: =IF($F31="","",INDEX('Каталог поиска'!$C$2:$C$998,$F31)) -> S | D31: =IF(OR($F31="",E31=0,INDEX('Каталог поиска'!$D$2:$D$998,$F31)=0),"",IFERROR(INDEX('По размерам'!$A$2:$TY$86,MATCH($D$5,'По размерам'!$A$2:$A$86,0),INDEX('Каталог поиска'!$D$2:$D$998,$F31)),"")) | E31: =IF(OR($F31="",INDEX('Каталог поиска'!$D$2:$D$998,$F31)=0),"",IFERROR(INDEX('Количество значений'!$A$2:$TY$86,MATCH($D$5,'Количество значений'!$A$2:$A$86,0),INDEX('Каталог поиска'!$D$2:$D$998,$F31)),"")) | F31: =IFERROR(MATCH(19,'Каталог поиска'!$F$2:$F$998,0),"") -> 19
A32: =IF(F32="","",20) -> 20 | B32: =IF($F32="","",INDEX('Каталог поиска'!$B$2:$B$998,$F32)) -> Section | C32: =IF($F32="","",INDEX('Каталог поиска'!$C$2:$C$998,$F32)) -> T | D32: =IF(OR($F32="",E32=0,INDEX('Каталог поиска'!$D$2:$D$998,$F32)=0),"",IFERROR(INDEX('По размерам'!$A$2:$TY$86,MATCH($D$5,'По размерам'!$A$2:$A$86,0),INDEX('Каталог поиска'!$D$2:$D$998,$F32)),"")) | E32: =IF(OR($F32="",INDEX('Каталог поиска'!$D$2:$D$998,$F32)=0),"",IFERROR(INDEX('Количество значений'!$A$2:$TY$86,MATCH($D$5,'Количество значений'!$A$2:$A$86,0),INDEX('Каталог поиска'!$D$2:$D$998,$F32)),"")) | F32: =IFERROR(MATCH(20,'Каталог поиска'!$F$2:$F$998,0),"") -> 20
A33: =IF(F33="","",21) -> 21 | B33: =IF($F33="","",INDEX('Каталог поиска'!$B$2:$B$998,$F33)) -> RIM | C33: =IF($F33="","",INDEX('Каталог поиска'!$C$2:$C$998,$F33)) -> U | D33: =IF(OR($F33="",E33=0,INDEX('Каталог поиска'!$D$2:$D$998,$F33)=0),"",IFERROR(INDEX('По размерам'!$A$2:$TY$86,MATCH($D$5,'По размерам'!$A$2:$A$86,0),INDEX('Каталог поиска'!$D$2:$D$998,$F33)),"")) | E33: =IF(OR($F33="",INDEX('Каталог поиска'!$D$2:$D$998,$F33)=0),"",IFERROR(INDEX('Количество значений'!$A$2:$TY$86,MATCH($D$5,'Количество значений'!$A$2:$A$86,0),INDEX('Каталог поиска'!$D$2:$D$998,$F33)),"")) | F33: =IFERROR(MATCH(21,'Каталог поиска'!$F$2:$F$998,0),"") -> 21
A34: =IF(F34="","",22) -> 22 | B34: =IF($F34="","",INDEX('Каталог поиска'!$B$2:$B$998,$F34)) -> Inch | C34: =IF($F34="","",INDEX('Каталог поиска'!$C$2:$C$998,$F34)) -> V | D34: =IF(OR($F34="",E34=0,INDEX('Каталог поиска'!$D$2:$D$998,$F34)=0),"",IFERROR(INDEX('По размерам'!$A$2:$TY$86,MATCH($D$5,'По размерам'!$A$2:$A$86,0),INDEX('Каталог поиска'!$D$2:$D$998,$F34)),"")) | E34: =IF(OR($F34="",INDEX('Каталог поиска'!$D$2:$D$998,$F34)=0),"",IFERROR(INDEX('Количество значений'!$A$2:$TY$86,MATCH($D$5,'Количество значений'!$A$2:$A$86,0),INDEX('Каталог поиска'!$D$2:$D$998,$F34)),"")) | F34: =IFERROR(MATCH(22,'Каталог поиска'!$F$2:$F$998,0),"") -> 22
A35: =IF(F35="","",23) -> 23 | B35: =IF($F35="","",INDEX('Каталог поиска'!$B$2:$B$998,$F35)) -> Load | C35: =IF($F35="","",INDEX('Каталог поиска'!$C$2:$C$998,$F35)) -> W | D35: =IF(OR($F35="",E35=0,INDEX('Каталог поиска'!$D$2:$D$998,$F35)=0),"",IFERROR(INDEX('По размерам'!$A$2:$TY$86,MATCH($D$5,'По размерам'!$A$2:$A$86,0),INDEX('Каталог поиска'!$D$2:$D$998,$F35)),"")) | E35: =IF(OR($F35="",INDEX('Каталог поиска'!$D$2:$D$998,$F35)=0),"",IFERROR(INDEX('Количество значений'!$A$2:$TY$86,MATCH($D$5,'Количество значений'!$A$2:$A$86,0),INDEX('Каталог поиска'!$D$2:$D$998,$F35)),"")) | F35: =IFERROR(MATCH(23,'Каталог поиска'!$F$2:$F$998,0),"") -> 23
A36: =IF(F36="","",24) -> 24 | B36: =IF($F36="","",INDEX('Каталог поиска'!$B$2:$B$998,$F36)) -> Pattern | C36: =IF($F36="","",INDEX('Каталог поиска'!$C$2:$C$998,$F36)) -> X | D36: =IF(OR($F36="",E36=0,INDEX('Каталог поиска'!$D$2:$D$998,$F36)=0),"",IFERROR(INDEX('По размерам'!$A$2:$TY$86,MATCH($D$5,'По размерам'!$A$2:$A$86,0),INDEX('Каталог поиска'!$D$2:$D$998,$F36)),"")) | E36: =IF(OR($F36="",INDEX('Каталог поиска'!$D$2:$D$998,$F36)=0),"",IFERROR(INDEX('Количество значений'!$A$2:$TY$86,MATCH($D$5,'Количество значений'!$A$2:$A$86,0),INDEX('Каталог поиска'!$D$2:$D$998,$F36)),"")) | F36: =IFERROR(MATCH(24,'Каталог поиска'!$F$2:$F$998,0),"") -> 24
A37: =IF(F37="","",25) -> 25 | B37: =IF($F37="","",INDEX('Каталог поиска'!$B$2:$B$998,$F37)) -> Tire type | C37: =IF($F37="","",INDEX('Каталог поиска'!$C$2:$C$998,$F37)) -> Y | D37: =IF(OR($F37="",E37=0,INDEX('Каталог поиска'!$D$2:$D$998,$F37)=0),"",IFERROR(INDEX('По размерам'!$A$2:$TY$86,MATCH($D$5,'По размерам'!$A$2:$A$86,0),INDEX('Каталог поиска'!$D$2:$D$998,$F37)),"")) | E37: =IF(OR($F37="",INDEX('Каталог поиска'!$D$2:$D$998,$F37)=0),"",IFERROR(INDEX('Количество значений'!$A$2:$TY$86,MATCH($D$5,'Количество значений'!$A$2:$A$86,0),INDEX('Каталог поиска'!$D$2:$D$998,$F37)),"")) | F37: =IFERROR(MATCH(25,'Каталог поиска'!$F$2:$F$998,0),"") -> 25
A38: =IF(F38="","",26) -> 26 | B38: =IF($F38="","",INDEX('Каталог поиска'!$B$2:$B$998,$F38)) -> TCE SPEC No. | C38: =IF($F38="","",INDEX('Каталог поиска'!$C$2:$C$998,$F38)) -> Z | D38: =IF(OR($F38="",E38=0,INDEX('Каталог поиска'!$D$2:$D$998,$F38)=0),"",IFERROR(INDEX('По размерам'!$A$2:$TY$86,MATCH($D$5,'По размерам'!$A$2:$A$86,0),INDEX('Каталог поиска'!$D$2:$D$998,$F38)),"")) | E38: =IF(OR($F38="",INDEX('Каталог поиска'!$D$2:$D$998,$F38)=0),"",IFERROR(INDEX('Количество значений'!$A$2:$TY$86,MATCH($D$5,'Количество значений'!$A$2:$A$86,0),INDEX('Каталог поиска'!$D$2:$D$998,$F38)),"")) | F38: =IFERROR(MATCH(26,'Каталог поиска'!$F$2:$F$998,0),"") -> 26
A39: =IF(F39="","",27) -> 27 | B39: =IF($F39="","",INDEX('Каталог поиска'!$B$2:$B$998,$F39)) -> IPC No. | C39: =IF($F39="","",INDEX('Каталог поиска'!$C$2:$C$998,$F39)) -> AA | D39: =IF(OR($F39="",E39=0,INDEX('Каталог поиска'!$D$2:$D$998,$F39)=0),"",IFERROR(INDEX('По размерам'!$A$2:$TY$86,MATCH($D$5,'По размерам'!$A$2:$A$86,0),INDEX('Каталог поиска'!$D$2:$D$998,$F39)),"")) | E39: =IF(OR($F39="",INDEX('Каталог поиска'!$D$2:$D$998,$F39)=0),"",IFERROR(INDEX('Количество значений'!$A$2:$TY$86,MATCH($D$5,'Количество значений'!$A$2:$A$86,0),INDEX('Каталог поиска'!$D$2:$D$998,$F39)),"")) | F39: =IFERROR(MATCH(27,'Каталог поиска'!$F$2:$F$998,0),"") -> 27
A40: =IF(F40="","",28) -> 28 | B40: =IF($F40="","",INDEX('Каталог поиска'!$B$2:$B$998,$F40)) -> Code No. | C40: =IF($F40="","",INDEX('Каталог поиска'!$C$2:$C$998,$F40)) -> AB | D40: =IF(OR($F40="",E40=0,INDEX('Каталог поиска'!$D$2:$D$998,$F40)=0),"",IFERROR(INDEX('По размерам'!$A$2:$TY$86,MATCH($D$5,'По размерам'!$A$2:$A$86,0),INDEX('Каталог поиска'!$D$2:$D$998,$F40)),"")) | E40: =IF(OR($F40="",INDEX('Каталог поиска'!$D$2:$D$998,$F40)=0),"",IFERROR(INDEX('Количество значений'!$A$2:$TY$86,MATCH($D$5,'Количество значений'!$A$2:$A$86,0),INDEX('Каталог поиска'!$D$2:$D$998,$F40)),"")) | F40: =IFERROR(MATCH(28,'Каталог поиска'!$F$2:$F$998,0),"") -> 28
A41: =IF(F41="","",29) -> 29 | B41: =IF($F41="","",INDEX('Каталог поиска'!$B$2:$B$998,$F41)) -> Number | C41: =IF($F41="","",INDEX('Каталог поиска'!$C$2:$C$998,$F41)) -> AC | D41: =IF(OR($F41="",E41=0,INDEX('Каталог поиска'!$D$2:$D$998,$F41)=0),"",IFERROR(INDEX('По размерам'!$A$2:$TY$86,MATCH($D$5,'По размерам'!$A$2:$A$86,0),INDEX('Каталог поиска'!$D$2:$D$998,$F41)),"")) | E41: =IF(OR($F41="",INDEX('Каталог поиска'!$D$2:$D$998,$F41)=0),"",IFERROR(INDEX('Количество значений'!$A$2:$TY$86,MATCH($D$5,'Количество значений'!$A$2:$A$86,0),INDEX('Каталог поиска'!$D$2:$D$998,$F41)),"")) | F41: =IFERROR(MATCH(29,'Каталог поиска'!$F$2:$F$998,0),"") -> 29
A42: =IF(F42="","",30) -> 30 | B42: =IF($F42="","",INDEX('Каталог поиска'!$B$2:$B$998,$F42)) -> SIDE MC Group | C42: =IF($F42="","",INDEX('Каталог поиска'!$C$2:$C$998,$F42)) -> AD | D42: =IF(OR($F42="",E42=0,INDEX('Каталог поиска'!$D$2:$D$998,$F42)=0),"",IFERROR(INDEX('По размерам'!$A$2:$TY$86,MATCH($D$5,'По размерам'!$A$2:$A$86,0),INDEX('Каталог поиска'!$D$2:$D$998,$F42)),"")) | E42: =IF(OR($F42="",INDEX('Каталог поиска'!$D$2:$D$998,$F42)=0),"",IFERROR(INDEX('Количество значений'!$A$2:$TY$86,MATCH($D$5,'Количество значений'!$A$2:$A$86,0),INDEX('Каталог поиска'!$D$2:$D$998,$F42)),"")) | F42: =IFERROR(MATCH(30,'Каталог поиска'!$F$2:$F$998,0),"") -> 30
A43: =IF(F43="","",31) -> 31 | B43: =IF($F43="","",INDEX('Каталог поиска'!$B$2:$B$998,$F43)) -> Set position | C43: =IF($F43="","",INDEX('Каталог поиска'!$C$2:$C$998,$F43)) -> AE | D43: =IF(OR($F43="",E43=0,INDEX('Каталог поиска'!$D$2:$D$998,$F43)=0),"",IFERROR(INDEX('По размерам'!$A$2:$TY$86,MATCH($D$5,'По размерам'!$A$2:$A$86,0),INDEX('Каталог поиска'!$D$2:$D$998,$F43)),"")) -> 153.25 | E43: =IF(OR($F43="",INDEX('Каталог поиска'!$D$2:$D$998,$F43)=0),"",IFERROR(INDEX('Количество значений'!$A$2:$TY$86,MATCH($D$5,'Количество значений'!$A$2:$A$86,0),INDEX('Каталог поиска'!$D$2:$D$998,$F43)),"")) -> 4 | F43: =IFERROR(MATCH(31,'Каталог поиска'!$F$2:$F$998,0),"") -> 31
A44: =IF(F44="","",32) -> 32 | B44: =IF($F44="","",INDEX('Каталог поиска'!$B$2:$B$998,$F44)) -> Set position(+/-) | C44: =IF($F44="","",INDEX('Каталог поиска'!$C$2:$C$998,$F44)) -> AF | D44: =IF(OR($F44="",E44=0,INDEX('Каталог поиска'!$D$2:$D$998,$F44)=0),"",IFERROR(INDEX('По размерам'!$A$2:$TY$86,MATCH($D$5,'По размерам'!$A$2:$A$86,0),INDEX('Каталог поиска'!$D$2:$D$998,$F44)),"")) -> 1.5 | E44: =IF(OR($F44="",INDEX('Каталог поиска'!$D$2:$D$998,$F44)=0),"",IFERROR(INDEX('Количество значений'!$A$2:$TY$86,MATCH($D$5,'Количество значений'!$A$2:$A$86,0),INDEX('Каталог поиска'!$D$2:$D$998,$F44)),"")) -> 4 | F44: =IFERROR(MATCH(32,'Каталог поиска'!$F$2:$F$998,0),"") -> 32
A45: =IF(F45="","",33) -> 33 | B45: =IF($F45="","",INDEX('Каталог поиска'!$B$2:$B$998,$F45)) -> Remarks | C45: =IF($F45="","",INDEX('Каталог поиска'!$C$2:$C$998,$F45)) -> AG | D45: =IF(OR($F45="",E45=0,INDEX('Каталог поиска'!$D$2:$D$998,$F45)=0),"",IFERROR(INDEX('По размерам'!$A$2:$TY$86,MATCH($D$5,'По размерам'!$A$2:$A$86,0),INDEX('Каталог поиска'!$D$2:$D$998,$F45)),"")) | E45: =IF(OR($F45="",INDEX('Каталог поиска'!$D$2:$D$998,$F45)=0),"",IFERROR(INDEX('Количество значений'!$A$2:$TY$86,MATCH($D$5,'Количество значений'!$A$2:$A$86,0),INDEX('Каталог поиска'!$D$2:$D$998,$F45)),"")) | F45: =IFERROR(MATCH(33,'Каталог поиска'!$F$2:$F$998,0),"") -> 33
...

Sheet Обзор
B2: ПАРАМЕТРЫ ПО SIZE
B4: Единая таблица средних параметров из файлов 1st и 2st
B7: 85 размеров | D7: 534 параметра
B11: Открыть сводную таблицу →
B14: 1. Откройте сводную таблицу и выберите нужный Size через фильтр первого столбца.
B16: 2. Тёмно-синие заголовки — параметры 1st, синие — параметры 2st. Size закреплён при прокрутке.
B18: 3. Количество значений для каждого среднего доступно на отдельном листе.
B21: Количество значений → | D21: Инструкция →
B24: Средние описывают исходную выборку. Пустые и текст пропускаются; нули учитываются.
B27: Поиск параметров: выбор 1ST / 2ST →

Sheet По размерам
A1: Size | B1: 1st | Строк исходных данных | C1: 1st | Рисунок | D1: 1st | Оборудование | E1: 1st | Группа | F1: 1st | Building Size | G1: 1st | AE | Set position | H1: 1st | AF | Set position(+/-) | I1: 1st | AJ | Set position | J1: 1st | AL | Set position(+/-) | K1: 1st | AR | Set position | L1: 1st | AS | Set position(+/-) | M1: 1st | AY | Set position | N1: 1st | AZ | Set position(+/-) | O1: 1st | BF | Set position | P1: 1st | BG | Set position(+/-) | Q1: 1st | BM | Set position | R1: 1st | BN | Set position(+/-) | S1: 1st | BT | Set position | T1: 1st | BU | Set position(+/-) | U1: 1st | BW | BEAD set width (mm) | V1: 1st | BX | BEAD set width (mm) +/- | W1: 1st | BZ | Band drum main unit width | X1: 1st | CA | Band drum width | Y1: 1st | CD | Gum band width | Z1: 1st | CF | S/W gum band width | AA1: 1st | CI | Spacer width | AB1: 1st | CJ | Drum circum (SIDE/IL) | AC1: 1st | CK | Drum circum (SIDE/IL) +/- | AD1: 1st | CL | Drum circum (MAX) | AE1: 1st | CM | Drum circum (MAX) +/- | AF1: 1st | CT | IL width | AG1: 1st | CU | IL width +/- | AH1: 1st | CV | IL Angle gauge | AI1: 1st | CW | IL Length circum | AJ1: 1st | CX | IL Mass | AK1: 1st | CZ | CCH width | AL1: 1st | DA | CCH width +/- | AM1: 1st | DB | CCH gauge | AN1: 1st | DC | CCH Length circum | AO1: 1st | DD | CCH Mass | AP1: 1st | DF | 1P width | AQ1: 1st | DG | 1P width +/- | AR1: 1st | DH | 1P gauge | AS1: 1st | DI | 1P Length circum | AT1: 1st | DJ | 1P Mass | AU1: 1st | DL | 2P width | AV1: 1st | DM | 2P width +/- | AW1: 1st | DN | 2P gauge | AX1: 1st | DO | 2P Length circum | AY1: 1st | DP | 2P Mass | AZ1: 1st | DR | FL width | BA1: 1st | DS | FL width +/- | BB1: 1st | DT | FL gauge | BC1: 1st | DU | FL Length circum Value is temp | BD1: 1st | DV | FL Mass | BE1: 1st | DX | BD width(Diameter) | BF1: 1st | EA | BD Length circum | BG1: 1st | EB | BD Mass | BH1: 1st | ED | BF width | BI1: 1st | EE | BF width +/- | BJ1: 1st | EG | BF Length circum | BK1: 1st | EH | BF Mass | BL1: 1st | EJ | TPI width | BM1: 1st | EK | TPI width +/- | BN1: 1st | EN | TPI Mass | BO1: 1st | EQ | SIDE width | BP1: 1st | ER | SIDE width +/- | BQ1: 1st | ES | SIDE Angle gauge | BR1: 1st | ET | SIDE Length circum | BS1: 1st | EU | SIDE Mass(g/m) | BT1: 1st | EV | SIDE Mass Tire | BU1: 1st | EX | AGS width | BV1: 1st | EY | AGS width +/- | BW1: 1st | EZ | AGS Angle gauge | BX1: 1st | FA | AGS Length circum | BY1: 1st | FB | AGS Mass | BZ1: 1st | FC | AGS Mass tire | CA1: 1st | FE | 2NDBF width | CB1: 1st | FF | 2NDBF width +/- | CC1: 1st | FI | 2NDBF Mass | CD1: 1st | FL | 1P B1 Gauge | CE1: 1st | FM | 1P B1 Width-1 | CF1: 1st | FN | 1P B1 Set-1 | CG1: 1st | FO | 1P B1 Width-2 | CH1: 1st | FP | 1P B1 Set-2 | CI1: 1st | FS | 1P T1 Gauge | CJ1: 1st | FT | 1P T1 Width-1 | CK1: 1st | FU | 1P T1 Set-1 | CL1: 1st | FV | 1P T1 Width-2 | CM1: 1st | FW | 1P T1 Set-2 | CN1: 1st | FZ | 1P TPI Gauge | CO1: 1st | GA | 1P TPI Width | CP1: 1st | GB | 1P TPI Set | CQ1: 1st | GH | 1P T2 Gauge | CR1: 1st | GI | 1P T2 Width-1 | CS1: 1st | GJ | 1P T2 Set-1 | CT1: 1st | GS | 2P T1 Gauge | CU1: 1st | GT | 2P T1 Width-1 | CV1: 1st | GU | 2P T1 Set-1 | CW1: 1st | GV | 2P T1 Width-2 | CX1: 1st | GW | 2P T1 Set-2 | CY1: 1st | GZ | 2P T2 Gauge | CZ1: 1st | HA | 2P T2 Width-1 | DA1: 1st | HB | 2P T2 Set-1 | DB1: 1st | HC | SQ Gauge +/- | DC1: 1st | HD | SQ Width-1 +/- | DD1: 1st | HE | SQ Set-1 +/- | DE1: 1st | HF | SQ Width-2 +/- | DF1: 1st | HG | SQ Set-2 +/- | DG1: 1st | HH | SQ Width-3 +/- | DH1: 1st | HI | SideWidth | DI1: 1st | HJ | Side Width +/- | DJ1: 1st | HK | AGS set | DK1: 1st | HL | AGS set +/- | DL1: 1st | HM | TPI set | DM1: 1st | HN | TPI set +/- | DN1: 1st | HO | SIDE set | DO1: 1st | HP | SIDE set +/- | DP1: 1st | HQ | 2NDBF set | DQ1: 1st | HR | 2NDBF set +/- | DR1: 1st | HS | Band Mass | DS1: 1st | HT | Band Mass +/- | DT1: 1st | HU | Auto1 ST p1 | DU1: 1st | HW | Coefficient | DV1: 1st | HX | Auto1 ST p3 | DW1: 1st | HY | ST Pressure(High) (Mpa) | DX1: 1st | IA | ST Pressure(Low)(Mpa) | DY1: 1st | IB | IL | DZ1: 1st | IC | SIDE | EA1: 1st | ID | 1PLY | EB1: 1st | IE | 2PLY | EC1: 1st | IF | FLIPPER | ED1: 1st | IP | R1006 Tire Size (Inch) | EE1: 1st | IV | R1012 Band Drum Circumference (mm) | EF1: 1st | IW | R1013 Bead Lock Width (mm) | EG1: 1st | IX | R1014 KB Drum Expansion diameter(2P Down Apply) (mm) | EH1: 1st | IY | R1015 KB Drum Segment Width (mm) | EI1: 1st | JD | R1020 I/L Length Measuring Data (mm) | EJ1: 1st | JE | R1021 BP#1 Length Measuring Data (mm) | EK1: 1st | JF | R1022 BP#2 Length Measuring Data (mm) | EL1: 1st | JG | R1023 S/W Length Measuring Data (mm) | EM1: 1st | JH | R1024 RFT Length Measuring Data (mm) | EN1: 1st | JJ | R1026 USR PLY-ST Start Position (mm) | EO1: 1st | JK | R1027 USR PLY-ST End Position (mm) | EP1: 1st | JL | R1028 USR RFT-ST Start Position (mm) | EQ1: 1st | JM | R1029 S/W Out Side Width (mm) | ER1: 1st | JN | R1030 I/L Width (mm) | ES1: 1st | JO | R1031 BP1 Width (mm) | ET1: 1st | JP | R1032 BP2 Width (mm) | EU1: 1st | JQ | R1033 FL Width (mm) | EV1: 1st | JR | R1034 S/W Width Inside Guide Position (mm) | EW1: 1st | JS | R1035 S/W Width (mm) | EX1: 1st | JT | R1036 RFT Width (mm) | EY1: 1st | JU | R1037 RFT Width Inside Guide Position (mm) | EZ1: 1st | JV | R1038 Bead Width (mm) | FA1: 1st | JW | R1039 FL Width Check Position (mm) | FB1: 1st | JX | R1040 C-CH Outside Set Position (mm) | FC1: 1st | JY | R1041 Bead Lock Position (degree) | FD1: 1st | JZ | R1042 S/W Apply Start (degree) | FE1: 1st | KA | R1043 BP#2 Apply Start Spotting (degree) | FF1: 1st | KB | R1044 BP#1 Apply Start Spotting (degree) | FG1: 1st | KC | R1045 FL Apply Start Spotting (degree) | FH1: 1st | KD | R1046 GC Take Out Spotting (degree) | FI1: 1st | KE | R1047 RFT start Spotting (degree) | FJ1: 1st | KF | R1048 BAND Takeout Drum Expand Time (0,1sec.) | FK1: 1st | KG | R1049 BAND Takeout Drum Collapse Time (0,1sec.) | FL1: 1st | KH | R1050 S/W Tip Jam Time (0,1sec.) | FM1: 1st | KI | R1051 S/W Rear Jam Time (0,1sec.) | FN1: 1st | KJ | R1052 RFT Front Press Time (0,1sec.) | FO1: 1st | KK | R1053 S/W Tip Heating Time (0,1sec.) | FP1: 1st | KL | R1054 S/W Rear Heating Time (0,1sec.) | FQ1: 1st | KM | R1055 RFT Tip Heating Time (0,1sec.) | FR1: 1st | KN | R1056 RFT Rear Heating Time (0,1sec.) | FS1: 1st | KR | R1060 UST LowSpeed (10m/min) | FT1: 1st | KS | R1061 UST HighSpeed (10m/min) | FU1: 1st | KT | R1062 BAND Drum.S/W speed (10m/min) | FV1: 1st | KV | R1064 USR 2P-Up/Down Stitching Start Position (mm) | FW1: 1st | KW | R1065 USR 2P-Up/Down Stitching End Position (mm) | FX1: 1st | KX | R1066 USR Side Stitching Start Position (mm) | FY1: 1st | KY | R1067 USR Side Stitching Turn Position (mm) | FZ1: 1st | KZ | R1068 USR Side Stitching End Position (mm) | GA1: 1st | LA | R1069 USR Side Roll Stitching Start Position (mm) | GB1: 1st | LB | R1070 USR Side Roll Stitching End Position (mm) | GC1: 1st | LC | R1071 B/S PLY Turn Up Start Position (mm) | GD1: 1st | LD | R1072 B/S PLY Turn Up End Position (mm) | GE1: 1st | LE | R1073 PLY Turn Up B/S Start Delay Timer (0,1sec.) | GF1: 1st | LF | R1074 PLY Turn Up Bladder Inflate Time (0,1sec.) | GG1: 1st | LG | R1075 PLY Turn Up Bladder Inflate Lock Time (0,1sec.) | GH1: 1st | LH | R1076 PLY Turn Up Bladder Exhaust time (0,1sec.) | GI1: 1st | LI | R1077 PLY Turn Up B/S Return Delay Timer (0,1sec.) | GJ1: 1st | LJ | R1078 B/S Bead Lock Time (sec.) | GK1: 1st | LK | R1079 Gum band width | GL1: 1st | LV | I/L Press Balance Offset (degree) | GM1: 1st | LW | I/L Press Applyer CV Pushing Range (mm, 0.1mm) | GN1: 1st | LX | R1092 USR Middle Stop Position (mm) | GO1: 1st | LY | R1093 USR Middle Stop Time (sec.) | GP1: 1st | LZ | R1094 USR Speed change position (mm) | GQ1: 1st | PG | M/C mode (1:K1S / 2:KBN2) | GR1: 1st | PX | BOM_SIDE_PARTID | GS1: 1st | PY | BOM_SIDE_MACHINEGROUP | GT1: 1st | QA | BOM_SIDE_REVISIONNO | GU1: 1st | QB | BOM_SIDE_LENGTH | GV1: 1st | QC | BOM_IL_PARTID | GW1: 1st | QD | BOM_IL_MACHINEGROUP | GX1: 1st | QF | BOM_IL_REVISIONNO | GY1: 1st | QG | BOM_IL_LENGTH | GZ1: 1st | QH | BOM_CCH_PARTID | HA1: 1st | QI | BOM_CCH_MACHINEGROUP | HB1: 1st | QK | BOM_CCH_REVISIONNO | HC1: 1st | QL | BOM_CCH_LENGTH | HD1: 1st | QM | BOM_PLY1_PARTID | HE1: 1st | QN | BOM_PLY1_MACHINEGROUP | HF1: 1st | QP | BOM_PLY1_REVISIONNO | HG1: 1st | QQ | BOM_PLY1_LENGTH | HH1: 1st | QR | BOM_PLY2_PARTID | HI1: 1st | QS | BOM_PLY2_MACHINEGROUP | HJ1: 1st | QU | BOM_PLY2_REVISIONNO | HK1: 1st | QV | BOM_PLY2_LENGTH | HL1: 1st | QW | BOM_BDBF_PARTID | HM1: 1st | QX | BOM_BDBF_MACHINEGROUP | HN1: 1st | QZ | BOM_BDBF_REVISIONNO | HO1: 1st | RA | BOM_FL_PARTID | HP1: 1st | RB | BOM_FL_MACHINEGROUP | HQ1: 1st | RD | BOM_FL_REVISIONNO | HR1: 1st | RE | BOM_FL_LENGTH | HS1: 1st | RF | REF_PLYSQ1_REVISIONNO | HT1: 1st | RG | REF_PLYTPI1_REVISIONNO | HU1: 1st | RH | REF_PLYSQ2_REVISIONNO | HV1: 1st | RI | REF_PLYTPI2_REVISIONNO | HW1: 1st | RJ | REF_BEAD_REVISIONNO | HX1: 1st | RK | REF_CCH_TREAT_REVISIONNO | HY1: 1st | RL | REF_PLY1_TREAT_REVISIONNO | HZ1: 1st | RM | REF_PLU2_TREAT_REVISIONNO | IA1: 1st | RN | REF_FL_TREAT_REVISIONNO | IB1: 1st | RO | IL Mass | IC1: 1st | RP | CCH Mass | ID1: 1st | RQ | PLY1 - Mass | IE1: 1st | RR | PLY2 - Mass | IF1: 1st | RS | FL Mass | IG1: 1st | RT | BEAD - Mass | IH1: 1st | RU | BBF - Mass | II1: 1st | RX | S/W gum band width1 | IJ1: 1st | RY | S/W gauge criteria | IK1: 1st | SA | S/W gum band width2 | IL1: 1st | SD | PLYSQ1S_REVISIONNO | IM1: 1st | SG | PLYSQ2S_REVISIONNO | IN1: 1st | SH | IL_COEFFICIENT | IO1: 1st | SI | 1P_COEEFICIENT | IP1: 1st | SJ | 2P_COEEFICIENT | IQ1: 1st | SK | SIDE_ADJUSTMENT | IR1: 1st | SL | PRD_CODE_INVALID | IS1: 1st | SM | PLY1_TPI_REQUIRED | IT1: 1st | SN | PLY2_TPI_REQUIRED | IU1: 1st | SO | SIDE_DATA_INVALID | IV1: 1st | SP | IL_DATA_INVALID | IW1: 1st | SQ | CCH_DATA_INVALID | IX1: 1st | SR | CCH_REVISION_INVALID | IY1: 1st | SS | PLY1_DATA_INVALID | IZ1: 1st | ST | PLY2_DATA_INVALID | JA1: 1st | SU | PLY2_REVISION_INVALID | JB1: 1st | SV | FL_DATA_INVALID | JC1: 1st | SW | FL_REVISION_INVALID | JD1: 1st | SX | BDBF_DATA_INVALID | JE1: 1st | SY | CCH_REQUIRED | JF1: 1st | SZ | PLY2_REQUIRED | JG1: 1st | TA | FL_REQUIRED | JH1: 1st | TB | PROCESS1ST_056_UNIT:10M/MIN | JI1: 1st | TC | PROCESS1ST_057_UNIT:10M/MIN | JJ1: 1st | TD | Bead width(mm) | JK1: 1st | TN | Check building MC with spec data bank Size_TYPE | JL1: 2st | Строк исходных данных | JM1: 2st | Рисунок | JN1: 2st | Оборудование | JO1: 2st | Группа | JP1: 2st | Building Size | JQ1: 2st | AC | Set position | JR1: 2st | AF | Mass | JS1: 2st | AW | SL Pitch | JT1: 2st | AX | Layer set P1 | JU1: 2st | AY | Layer set P2 | JV1: 2st | AZ | Layer set P3 | JW1: 2st | BA | Layer set P4 | JX1: 2st | BB | Layer set P5 | JY1: 2st | BC | Layer set P6 | JZ1: 2st | BH | Layer set A | KA1: 2st | BI | Layer set B | KB1: 2st | BJ | Layer set C | KC1: 2st | BK | Layer set D | KD1: 2st | BL | Layer set E | KE1: 2st | BM | Layer set F | KF1: 2st | BN | Layer set G | KG1: 2st | BO | Layer set H | KH1: 2st | BP | Layer set I | KI1: 2st | BR | Layer set K | KJ1: 2st | BS | Layer set L | KK1: 2st | BT | BT Drum - Circumference | KL1: 2st | CV | MSE (Form center) | KM1: 2st | CW | MSE (Form center) +/- | KN1: 2st | CX | NON DT Side ending (From center) | KO1: 2st | CY | NON DT Side ending (From center) +/- | KP1: 2st | CZ | PLY Turn up (From center) | KQ1: 2st | DA | PLY Turn up (From center) +/- | KR1: 2st | DB | GT Mass(g) | KS1: 2st | DC | GT Mass(g) +/- | KT1: 2st | DD | GT width | KU1: 2st | DE | GT Circurmference standard | KV1: 2st | DF | GT Circurmference track record (trial) | KW1: 2st | DG | GT Circurmference maximum | KX1: 2st | DH | AGS position | KY1: 2st | DI | Green case circumference on turn up width | KZ1: 2st | DK | 1st Belt Width | LA1: 2st | DM | 1st Belt Angle | LB1: 2st | DN | Belt 1 gauge(mm) | LC1: 2st | DO | Coefficient 1Belt for length | LD1: 2st | DP | 1st Belt Length | LE1: 2st | DQ | 1st Belt Mass | LF1: 2st | DS | 2nd Belt Width | LG1: 2st | DU | 2nd Belt Angle | LH1: 2st | DV | Belt 2 gauge(mm) | LI1: 2st | DW | Coefficient 2Belt for length | LJ1: 2st | DX | 2nd Belt Length | LK1: 2st | DY | 2nd Belt Mass | LL1: 2st | EA | Beg Width for 1Belt | LM1: 2st | EC | Beg gauge for 1Belt | LN1: 2st | ED | Beg Length for 1 Belt | LO1: 2st | EE | Beg Mass for 1 Belt | LP1: 2st | EG | Beg Width for 2Belt | LQ1: 2st | EI | Beg gauge for 2Belt | LR1: 2st | EJ | Beg Length for 2Belt | LS1: 2st | EK | Beg Mass for 2Belt | LT1: 2st | EM | Spiral Belt Width | LU1: 2st | EN | Spiral Belt Width +/- | LV1: 2st | EO | Spiral Belt Gauge | LW1: 2st | EP | Circumrerence for SPL | LX1: 2st | EQ | Spiral Belt Length 1st Lay | LY1: 2st | ER | Spiral Belt Length 2nd Lay (Require P3) | LZ1: 2st | ES | Spiral Belt Length 3rd Lay (Require P4,P5) | MA1: 2st | ET | Spiral Belt Length 4th Lay (Require P6) | MB1: 2st | EU | Coefficient SPL for length | MC1: 2st | EV | Spiral Belt Length | MD1: 2st | EW | Spiral Belt Mass | ME1: 2st | EY | Cap Width | MF1: 2st | FA | Cap Gauge | MG1: 2st | FB | Coefficient TOP for length | MH1: 2st | FC | Consider SPL for TOP Length | MI1: 2st | FD | Cap Length | MJ1: 2st | FE | Cap Mass | MK1: 2st | FG | Base Width | ML1: 2st | FI | Base gauge | MM1: 2st | FJ | Base Length | MN1: 2st | FK | Base Mass | MO1: 2st | FP | Mini side Length | MP1: 2st | FQ | Mini side Mass | MQ1: 2st | FS | TUC Width | MR1: 2st | FU | TUC gauge | MS1: 2st | FV | TUC Length | MT1: 2st | FW | TUC Mass | MU1: 2st | FY | Antenna Position | MV1: 2st | GB | Antenna Length | MW1: 2st | GC | Antenna Mass | MX1: 2st | GD | TOP Total Mass | MY1: 2st | GN | Position (Hump line) | MZ1: 2st | GQ | Position (Center) | NA1: 2st | GV | Gauge (Center) | NB1: 2st | GW | Gauge (Hump) | NC1: 2st | GX | Gauge (Side) | ND1: 2st | GY | Shoulder width | NE1: 2st | GZ | Shoulder width +/- | NF1: 2st | HA | width | NG1: 2st | HB | width +/- | NH1: 2st | HC | length | NI1: 2st | HD | length +/- | NJ1: 2st | HM | R1006 Tire Size (Inch) | NK1: 2st | HR | R1011 NO6 ST SPECIFICATION (AFTER S/W TURN UP) | NL1: 2st | HS | R1012 BT Circumference(mm) | NM1: 2st | HT | R1013 O-ring Offset Value(mm) | NN1: 2st | HY | R1018 TREAD Not Use Length (mm) | NO1: 2st | HZ | R1019 BELT Stabilizer Ply Angle | NP1: 2st | IA | R1020 1BELT Stabilizer Ply Length (mm) | NQ1: 2st | IB | R1021 2BELT Stabilizer Ply Length (mm) | NR1: 2st | IC | R1022 3BELT Stabilizer Ply Length (mm) | NS1: 2st | ID | R1023 TREAD Length Measuring Data for Cut (mm) | NT1: 2st | IE | R0124 TREAD Length Measuring Data for Apply (mm) | NU1: 2st | IF | R1025 1BELT Stabilizer Ply Width (mm) | NV1: 2st | IG | R1026 2BELT Stabilizer Ply Width (mm) | NW1: 2st | IH | R1027 TREAD Width (mm) | NX1: 2st | IJ | R1029 Tread Heating Time (sec) | NY1: 2st | IM | R1032 2BELT SP Application Start Spotting (degree) | NZ1: 2st | IN | R1033 Spairal Layer Application1 Start Spotting (degree) | OA1: 2st | IO | R1034 Spairal Layer Application2 Start Spotting (degree) | OB1: 2st | IP | R1035 Tread Apply Start Spotting (degree) | OC1: 2st | IQ | R1036 Shaping Drum Balance Offset (degree) | OD1: 2st | IR | R1037 Shaping Drum GT Take Out Spotting (degree) | OE1: 2st | IT | R1039 BT Take Out Spotting (degree) | OF1: 2st | IU | R1040 SPL L&R Head Offset (L-Head based) (mm) | OG1: 2st | IV | R1041 Spiral Layer Pitch (mm) | OH1: 2st | IW | R1042 SPL Position 1 (mm) | OI1: 2st | IX | R1043 SPL Position 2 (mm) | OJ1: 2st | IY | R1044 SPL Position 3 (mm) | OK1: 2st | IZ | R1045 SPL Position 4 (mm) | OL1: 2st | JA | R1046 SPL Position 5 (mm) | OM1: 2st | JB | R1047 SPL Position 6 (mm) | ON1: 2st | JC | R1048 SPL Position 7 (mm) | OO1: 2st | JD | R1049 SPL Position 8 (mm) | OP1: 2st | JE | R1050 SPL Position 9 (mm) | OQ1: 2st | JF | R1051 SPL Position 10 (mm) | OR1: 2st | JG | R1052 GAP Spiral Layer Pitch (Layer Width+GAP Width) (mm) | OS1: 2st | JH | R1053 GAP Change Position (mm) | OT1: 2st | JI | R1054 SHAPING Drum Width Bead Lock Pos(Maximum Width) (mm) | OU1: 2st | JJ | R1055 SHAPING Drum Width Middle Shape Position (mm) | OV1: 2st | JK | R1056 SHAPING Drum Width DT S/W Turn Up Position (mm) | OW1: 2st | JL | R1057 SHAPING Drum Width BT Insert Position (mm) | OX1: 2st | JM | R1058 SHAPING Drum Width Full Shap Position (mm) | OY1: 2st | JP | R1061 Top Tread Stitcher Start Position (mm) | OZ1: 2st | JQ | R1062 Top Tread Stitcher End Position (mm) | PA1: 2st | JR | R1063 S/W Stitcher Start Position(Front/Rear) (mm) | PB1: 2st | JS | R1064 S/W Stitcher End Position(Front/Rear) (mm) | PC1: 2st | JT | R1065 BF Stitcher Start Position (mm) | PD1: 2st | JU | R1066 BF Stitcher End Position (mm) | PE1: 2st | JV | R1067 S/W Stitcher Traverse Intrpolation Start Pos(Frnt/Rr) (mm) | PF1: 2st | JW | R1068 S/W Stitcher Traverse End Pos(=0 Not Traverse) (mm) | PG1: 2st | KF | R1077 SHAPING Bladder High Pressure (MPa) Max 0.5MPa | PH1: 2st | KG | R1078 SHAPING Bladder Low Pressure (MPa) Max 0.5MPa | PI1: 2st | KM | R1084 Tread Stitcher In Wait Timer (sec.) | PJ1: 2st | KN | R1085 SHAPING Bladder Low Pressure Timer (Insert) (sec.) | PK1: 2st | KO | R1086 Upper Bladder Expand Wait Timer (Middle) (sec.) | PL1: 2st | KP | R1087 Upper Bladder Expand Timer (Middle) (sec.) | PM1: 2st | KQ | R1088 SHAPING Drum Width Move Wait Timer From Max to Inside (mm) | PN1: 2st | KR | R1089 Segment Extend Timer (sec.) | PO1: 2st | KS | R1090 SHAPING Bladder Low Pressure Wait Timer (Middle) (sec) | PP1: 2st | KT | R1091 SHAPING Bladder Low Pressure Timer (Middle) (sec.) | PQ1: 2st | KU | R1092 Upper Bladder Expand Wait Timer (Full) (sec.) | PR1: 2st | KV | R1093 Upper Bladder Expand Timer (Full) (sec.) | PS1: 2st | KW | R1094 SHAPING Drum Width Move Wait Time(When Full Shap) (sec) | PT1: 2st | KX | R1095 SHAPING Drum Width Move Wait Time-From Segm Exp.Width(sec) | PU1: 2st | KY | R1096 SHAPING Bladder High Pressure Wait Timer(Full) (sec.) | PV1: 2st | KZ | R1097 Upper Bladder Expand Timer (Turn-Up) (sec.) | PW1: 2st | LA | R1098 Upper Bladder Exhaust Wait Time (Turn-Up) (sec.) | PX1: 2st | LB | R1099 Upper/Lower Bladder Expand/Exhaust Time(Turn-Up) (sec.) | PY1: 2st | LC | R1100 Lower Bladder Expand Wait Timer (Turn-Up) (sec.) | PZ1: 2st | LD | R1101 Lower Bladder Expand Timer (Turn-Up) (sec.) | QA1: 2st | LE | R1102 Lower Bladder Expand/Exhaust Wait Time (Turn-Up) (sec.) | QB1: 2st | LF | R1103SHAPING Drum Width Move Wait Timer(When DT Turn Up) (sec.) | QC1: 2st | LG | R1104 SHAPING Bladder Low Pressure Wait Timer(Turn-Up) (sec.) | QD1: 2st | LH | R1105 SHAPING Bladder Low Pressure Timer (Turn-Up) (sec.) | QE1: 2st | LJ | R1107 Outer Turn-Up Bladder 2nd Exhaust Wait Time(Turn-Up)(sec.) | QF1: 2st | LK | R1108 Bladder Vacuum Time (sec.) | QG1: 2st | LL | R1109 Bladder Deflate Time (sec.) | QH1: 2st | LM | R1110 SHAPING Drum Width Expansion Delay Time (0,1sec.) | QI1: 2st | LN | R1111 O-ring Close Delay Time (sec.) | QJ1: 2st | LO | R1112 Bead Lock Collapse Delay Time (sec.) | QK1: 2st | LP | R1113 Rim Guard DT SHAPING Pre-exaust Time (sec.) | QL1: 2st | LQ | R1114 Outer Turn-Up Bladder 2nd Exhaust Time (Turn-Up) (sec.) | QM1: 2st | LW | R1120 Mechanical Drum Left Turn-Up Arm Out (sec.) | QN1: 2st | LX | R1121 Mechanical Drum Right Turn-Up Arm Out (sec.) | QO1: 2st | LY | R1122 Mechanical Drum Left Turn-Up Arm Return (sec.) | QP1: 2st | LZ | R1123 Mechanical Drum Right Turn-Up Arm Retrun (sec.) | QQ1: 2st | MB | R1125 GT Take Quick Exhaust Wait Time (sec.) | QR1: 2st | MG | R1130 BT Drum 1B Apply Speed (rpm) | QS1: 2st | MH | R1131 BT Drum 2B Apply Speed (rpm) | QT1: 2st | MI | R1132 BT Drum SPLay Apply Low Speed (rpm) | QU1: 2st | MJ | R1133 BT Drum SPLay Apply Hi Speed (rpm) | QV1: 2st | MK | R1134 BT Drum TREAD Apply Speed (rpm) | QW1: 2st | MM | R1136 SHAPING Drum Pre-expansion (mm) | QX1: 2st | MQ | R1140 FR Drum Width GC Maximum Position (mm) | QY1: 2st | MR | R1141 FR Drum Width Poly-Liner Take Out Position (mm) | QZ1: 2st | MS | R1142 FR Bladder Vacuum Time (GC Insert) (sec.) | RA1: 2st | MT | R1143 FR Bladder High Pressure Time (Middle) (sec.) | RB1: 2st | MU | R1144 FR Bladder Pressure Change Delay Time (Middle) (sec.) | RC1: 2st | MV | R1145 FR Bladder Low Pressure Time (Middle) (sec.) | RD1: 2st | MW | R1146 FR Width Move Delay Time (Middle) (sec.) | RE1: 2st | MX | R1147 FR Bead Lock Pressure Change Delay Time (Full) (sec.) | RF1: 2st | MY | R1148 FR Bead Lock High Pressure Time (Full) (sec.) | RG1: 2st | MZ | R1149 FR Bladder Low Pressure Time (Full) (sec.) | RH1: 2st | NA | R1150 FR Bladder High Pressure Change Delay Time (Full) (sec.) | RI1: 2st | NB | R1151 O-Ring Expand Delay Time (Full) (sec.) | RJ1: 2st | NC | R1152 FR Width GT Take Out Width Mov Delay Time (sec.) | RK1: 2st | ND | R1153 FR Bladder Exhaust Time (GT Take Out) (sec.) | RL1: 2st | NE | R1154 FR Bladder Vacuum Delay Time (GT Take Out) (sec.) | RM1: 2st | NF | R1155 FR Bladder Vacuum Time (GT Take Out) (sec.) | RN1: 2st | NG | R1156 FR Bead Lock Collapse Delay Time (GT Take Out) (sec.) | RO1: 2st | NH | R1157 Turn Up Arm Expand Delay Time (sec.) | RP1: 2st | NJ | R1159 Turn Up Maintenance Time (sec.) | RQ1: 2st | NK | R1160 Turn Up Arm Collapse Delay Time (sec.) | RR1: 2st | NM | R1162 Turn Up Arm Wide Check Time (sec.) | RS1: 2st | NN | R1163 No5.Stitcher Width Start Position (mm) | RT1: 2st | NO | R1164 No5.Stitcher Width Raise Up Position (mm) | RU1: 2st | NP | R1165 No5.Stitcher End Position (mm) | RV1: 2st | NQ | R1166 No5.Stitcher Arm Pressure Change Position (mm) | RW1: 2st | NR | R1167 No5.Stitcher Middle Position Move Delay Time (sec.) | RX1: 2st | NS | R1168 No5.Stitcher Width End Position Move Delay Time (sec.) | RY1: 2st | NT | R1169 No5.Stitcher Arm Open Delay Time (sec.) | RZ1: 2st | OK | BOM_BELT1_PARTID | SA1: 2st | OL | BOM_BELT1_MACHINEGROUP | SB1: 2st | ON | BOM_BELT1_REVISIONNO | SC1: 2st | OO | BOM_BELT1_LENGTH | SD1: 2st | OP | BOM_BELT2_PARTID | SE1: 2st | OQ | BOM_BELT2_MACHINEGROUP | SF1: 2st | OS | BOM_BELT2_REVISIONNO | SG1: 2st | OT | BOM_BELT2_LENGTH | SH1: 2st | OU | BOM_LAY_PARTID | SI1: 2st | OV | BOM_LAY_MACHINEGROUP | SJ1: 2st | OX | BOM_LAY_REVISIONNO | SK1: 2st | OY | BOM_LAY_LENGTH | SL1: 2st | OZ | BOM_TOP_PARTID | SM1: 2st | PA | BOM_TOP_MACHINEGROUP | SN1: 2st | PC | BOM_TOP_REVISIONNO | SO1: 2st | PD | BOM_TOP_LENGTH | SP1: 2st | PF | Belt 1 Mass (Treatment) | SQ1: 2st | PG | Belt 1 Mass (End gum) | SR1: 2st | PH | Belt 2 Mass (Treatment) | SS1: 2st | PI | Belt 2 Mass (End gum) | ST1: 2st | PJ | Top Mass mini side | SU1: 2st | PK | Top Mass after DT | SV1: 2st | PL | Top Mass cap | SW1: 2st | PM | Top Mass base | SX1: 2st | PN | Top Mass tuc | SY1: 2st | PO | Top Mass antenna | SZ1: 2st | PP | SPL_MASS | TA1: 2st | PQ | For database reference(Data key of Circum) | TB1: 2st | PR | For database reference(Data key of Circum)2 | TC1: 2st | PS | For database reference(Data key of O-Ring) | TD1: 2st | PT | Top Tread Width | TE1: 2st | PU | Wing Tip Width | TF1: 2st | PX | PRD_CODE_INVALID | TG1: 2st | PY | SPL_P1_VALID_CHECK | TH1: 2st | PZ | SPL_P2_VALID_CHECK | TI1: 2st | QA | SPL_P3_VALID_CHECK | TJ1: 2st | QB | SPL_REVISION_INVALID | TK1: 2st | QC | SPL_NO_NEED | TL1: 2st | QD | SPL_NEED | TM1: 2st | QE | SPL_P1 | TN1: 2st | QF | SPL_P3 | TO1: 2st | QG | PROCESS2ND_032_UNIT:10DEG | TP1: 2st | QH | CHECK_OF_SIDEWALLSTITCHER | TQ1: 2st | QI | CHECK_OF_TOPTREADSTITCHER | TR1: 2st | QJ | CHECK_OF_SW_ST_STOP | TS1: 2st | QK | Side set position | TT1: 2st | QL | Bead Set Width | TU1: 2st | QM | Bead Width | TV1: 2st | QN | Bead Ring Circumference | TW1: 2st | QQ | Check building MC with spec data bank Size_TYPE | TX1: 2st | QS | Low Bead Lock pressure | TY1: 2st | QT | High Bead Lock pressure
